Workbook
Name obref: 'O''Brien'!$B$2
Name wbpath: CELL("filename",Main!$A$1)
Name sheetname: MID(CELL("filename",Main!$A$1),FIND("]",CELL("filename",Main!$A$1))+1,255)

Sheet Main
A1: 1 | D1: =CELL("filename",A1) | Y1: W1 | Z1: system
B2: 20 | D2: =CELL("filename",Other!A1)
C3: tx | D3: =CELL("filename",'My Sheet'!A1)
D4: =CELL("filename",'O''Brien'!A1)
D5: =CELL("filename",Données!A1)
D6: =CELL("filename",'1Q'!A1)
D7: =CELL("filename",'Sheet (2)'!A1)
D8: =CELL("filename",other!B2:C3)
D9: =CELL("filename",INDIRECT("'My Sheet'!B2"))
D10: =CELL("filename",OFFSET(Other!A1,1,1))
D11: =CELL("FILENAME",Main!A1)
D12: =CELL("filename",obref)
D13: =CELL("filename")
D14: =CELL("address",Other!B2)
D15: =CELL("address",'My Sheet'!B2)
D16: =CELL("address",'O''Brien'!B2)
D17: =CELL("address",Données!B2)
D18: =CELL("address",'1Q'!B2)
D19: =CELL("address",'Sheet (2)'!B2)
D20: =CELL("address",Main!B2)
D21: =CELL("address",INDIRECT("'Sheet (2)'!C3"))
D22: =MID(CELL("filename",A1),FIND("]",CELL("filename",A1))+1,255)
D23: =RIGHT(CELL("filename",A1),LEN(CELL("filename",A1))-FIND("]",CELL("filename",A1)))
D24: =MID(CELL("filename",'My Sheet'!A1),FIND("]",CELL("filename",'My Sheet'!A1))+1,31)
D25: =LEFT(CELL("filename",A1),FIND("[",CELL("filename",A1))-1)
D26: =MID(CELL("filename",A1),FIND("[",CELL("filename",A1))+1,FIND("]",CELL("filename",A1))-FIND("[",CELL("filename",A1))-1)
D27: =SUBSTITUTE(LEFT(CELL("filename",A1),FIND("]",CELL("filename",A1))-1),"[","")
D28: =_xlfn.TEXTAFTER(CELL("filename",A1),"]")
D29: =_xlfn.TEXTBEFORE(_xlfn.TEXTAFTER(CELL("filename",A1),"["),"]")
D30: =LEN(CELL("filename",A1))
D31: =REPLACE(CELL("filename",A1),1,FIND("]",CELL("filename",A1)),"")
D32: =CELL("filename",Other!A1)=CELL("filename",other!A1)
D33: =wbpath
D34: =sheetname
D35: =FIND("]",CELL("filename",A1))
D36: =INFO("directory")
D37: =INFO("numfile")
D38: =INFO("origin")
D39: =INFO("osversion")
D40: =INFO("recalc")
...

Sheet Other
A1: 1
B2: 20
C3: tx

Sheet My Sheet
A1: 1 | D1: =CELL("filename",A1)
B2: 20 | D2: =CELL("filename",Main!A1)
C3: tx | D3: =MID(CELL("filename",A1),FIND("]",CELL("filename",A1))+1,255)
D4: =CELL("address",Main!B2)
D5: =CELL("address",B2)
D6: =CELL("address",'My Sheet'!B2)

Sheet O'Brien
A1: 1 | D1: =CELL("filename",A1)
B2: 20 | D2: =CELL("address",Other!B2)
C3: tx

Sheet Données
A1: 1
B2: 20
C3: tx

Sheet 1Q
A1: 1
B2: 20
C3: tx

Sheet Sheet (2)
A1: 1
B2: 20
C3: tx

Sheet Fmt
A1: 1 | D1: =CELL("format",A1)
A2: 1.5 | B2: 20 | D2: =CELL("format",A2)
A3: 1234 | C3: tx | D3: =CELL("format",A3)
A4: 0.5 | D4: =CELL("format",A4)
A5: 45000 | D5: =CELL("format",A5)
A6: left | D6: =CELL("format",A9)
A7: right | D7: =CELL("format",A10)
A8: center | D8: =CELL("prefix",A6)
A9: -5 | D9: =CELL("prefix",A7)
A10: 5 | D10: =CELL("prefix",A8)
A11: plain | D11: =CELL("prefix",A11)
A12: 7 | D12: =CELL("prefix",A1)
D13: =CELL("color",A9)
D14: =CELL("color",A1)
D15: =CELL("parentheses",A10)
D16: =CELL("parentheses",A1)
D17: =CELL("protect",A1)
D18: =CELL("protect",A12)
D19: =CELL("width",A1)
D20: =CELL("width",B1)
D21: =INDEX(CELL("width",B1),1,2)
D22: =COLUMNS(CELL("width",A1))
D23: =CELL("prefix",Z99)
D24: =CELL("format",Z99)
