Workbook

Sheet Sheet1
E1: =SUM(INDEX([1]Idx!$A$1:$A$5,SMALL({0,1},1)))
E2: =IF(TRUE,INDEX([1]Idx!$A$1:$A$5,SMALL({0,1},1)))
E3: =INDEX([1]Idx!$A$1:$A$5,SMALL({0,1},1))*2
E4: =INDEX([1]Idx!$A$1:$A$5,SMALL({0,1},1))
E5: =IFERROR(INDEX([1]Idx!$A$1:$A$5,SMALL({0,1},1)),"")
E6: =INDEX([1]Idx!$A$1:$A$5,SMALL({0,1},1))*2
E7: =INDEX([1]Idx!$A$1:$A$5,SMALL({2,3},2))
E8: =INDEX([1]Idx!$A$1:$A$5,SMALL({9,7},1))
E9: =INDEX([1]Idx!$A$1:$A$5,SMALL({1.9,3},1))
E10: =INDEX([1]Idx!$A$1:$A$5,-SMALL({1,3},1))
E11: =INDEX([1]Idx!$A$1:$A$5,SMALL({1,2},3))
E12: =ROWS(INDEX([1]Idx!$A$1:$A$5,SMALL({0,1},1)))
E13: =ROW(INDEX([1]Idx!$A$1:$A$5,SMALL({4,1},2)))
E14: =ISREF(INDEX([1]Idx!$A$1:$A$5,SMALL({4,1},2)))
E15: =INDEX([1]IdxErr!$A$1:$A$5,SMALL({4,1},2))
E16: =INDEX([1]Idx!$A$1:$A$9,SMALL({8,1},2))
E17: {=INDEX([1]Idx!$A$1:$A$5,SMALL({0,1},1))}
E18: {=IF(TRUE,INDEX([1]Idx!$A$1:$A$5,SMALL({0,1},1)))}
E19: {=IFERROR(INDEX([1]Idx!$A$1:$A$5,SMALL({0,1},1)),"")}
E20: {=IF(ROWS($E$20:E20)>2,"",INDEX([1]Idx!$B$1:$B$5,SMALL(IF([1]Idx!$A$1:$A$5>=2,IF([1]Idx!$A$1:$A$5<=4,ROW([1]Idx!$A$1:$A$5)-ROW([1]Idx!$A$1)+1)),ROWS($E$20:E20))))}
E21: {=IF(ROWS($E$20:E21)>2,"",INDEX([1]Idx!$B$1:$B$5,SMALL(IF([1]Idx!$A$1:$A$5>=2,IF([1]Idx!$A$1:$A$5<=4,ROW([1]Idx!$A$1:$A$5)-ROW([1]Idx!$A$1)+1)),ROWS($E$20:E21))))}
E22: {=INDEX([1]Idx!$B$1:$B$5,LARGE(INDEX(ROW([1]Idx!$A$1:$A$5)*([1]Idx!$A$1:$A$5>2),),1))}
E23: {=IFERROR(INDEX([1]Idx!$B$1:$B$100,SMALL(IF(([1]Idx!$A$1:$A$100=3),ROW([1]Idx!$B$1:$B$100),""),1)),"")}
E24: {=IFERROR(INDEX([1]Idx!$B$1:$B$100,SMALL(IF(([1]Idx!$A$1:$A$100=9),ROW([1]Idx!$B$1:$B$100),""),1)),"")}
E25: =INDEX([1]Idx!$A$1:$B$5,SMALL({3,1},2),SMALL({2,1},2))
E26: =SUM(INDEX([1]Idx!$A$1:$B$5,SMALL({0,1},1),SMALL({2,1},2)))
E27: =INDEX([1]Idx!$A$1:$B$5,SMALL({3,1},2),SMALL({0,1},1))*1
E32: =COUNTA(INDEX([1]IdxErr!$A$1:$A$9,SMALL({0,1},1)))
E33: {=INDEX([1]Idx!$A$1:$A$5,SMALL({0,1},1))+0}
E34: =IFERROR(INDEX([1]IdxErr!$A$1:$A$5,SMALL({4,1},2)),"x")
E35: =INDEX([1]Idx!$A$1:$A$5,"2")
E36: =INDEX([1]Idx!$A$1:$E$1,SMALL({0,1},1))
E37: =INDEX([1]Idx!$A$1:$A$5,FALSE)*1
E40: =VLOOKUP(165,[1]Ok!$A:$B,2,TRUE)
E41: =VLOOKUP(135,[1]Ok!$A:$B,2,TRUE)
E42: =VLOOKUP(180,[1]Ok!$A:$B,2,TRUE)
E43: =VLOOKUP(125,[1]Ok!$A:$B,2,TRUE)
E44: =VLOOKUP(100,[1]Ok!$A:$B,2,TRUE)
E45: =VLOOKUP(3,[1]Ok!$A:$B,2,TRUE)
E46: =VLOOKUP(2,[1]Ok!$A:$B,2,TRUE)
...

Sheet Loc
A10: 3 | B10: r10
A11: hdr | B11: r11
A12: 100 | B12: r12
A13: 110 | B13: r13
A14: 120 | B14: r14
A15: 130 | B15: r15
A16: 140 | B16: r16
A17: 150 | B17: r17
A18: 160 | B18: r18
A19: 170 | B19: r19
A20: 180 | B20: r20
A21: 5 | B21: r21
A22: 5 | B22: r22
A23: 5 | B23: r23
... A25: 5 | B25: r25

Sheet LocRow
J1: 3 | K1: hdr | L1: 100 | M1: 110 | N1: 120 | O1: 130 | P1: 140 | Q1: 150 | R1: 160 | S1: 170 | T1: 180 | U1: 5 | V1: 5 | W1: 5 | X1: 5 | Y1: 5
J2: c10 | K2: c11 | L2: c12 | M2: c13 | N2: c14 | O2: c15 | P2: c16 | Q2: c17 | R2: c18 | S2: c19 | T2: c20 | U2: c21 | V2: c22 | W2: c23 | X2: c24 | Y2: c25

Sheet LocTxt
A1: b | B1: t1
A2: d | B2: t2
A3: f | B3: t3
A4: h | B4: t4
A5: j | B5: t5
A6: a | B6: t6
A7: a | B7: t7
A8: a | B8: t8

Sheet LocDesc
A1: 50 | B1: d1
A2: 40 | B2: d2
A3: 30 | B3: d3
A4: 20 | B4: d4
A5: 10 | B5: d5

Sheet LocIdx
A1: 1 | B1: 10
A2: 2 | B2: 20
A3: 3 | B3: 30
A4: 4 | B4: 40
A5: 5 | B5: 50
